Workbook

Sheet 汇总
A1: 外周神经 scRNA 数据集 · 按物种 × 组织系统大类 重新分类
A2: 来源：合并文献检索_四层整合版.xlsx（Tier-1 Catalog 真源）｜去重键=代表Dataset_ID｜共 88 个独立数据集｜生成日期 2026-06-14 说明：左侧 3 列「物种(中文)/组织系统大类/主组织」为便捷分析【派生列·非真源】；组织系统大类按 Tissue 关键词归纳，命中 ≥4 个不同系统判为「多器官图谱/全身」；原始 21 列完整保留。
A6: 组织系统大类 | B6: 人 Human | C6: 鼠 Mouse | D6: 人鼠 Human;Mouse | E6: 数据集合计 | F6: 细胞数合计
A7: 周围神经节/神经干 | B7: =COUNTIFS(全部!$A$2:$A$89,"人 Human",全部!$B$2:$B$89,$A7) -> 3 | C7: =COUNTIFS(全部!$A$2:$A$89,"鼠 Mouse",全部!$B$2:$B$89,$A7) -> 3 | D7: =COUNTIFS(全部!$A$2:$A$89,"人鼠 Human;Mouse",全部!$B$2:$B$89,$A7) -> 0 | E7: =SUM(B7:D7) -> 6 | F7: =SUMIFS(全部!$R$2:$R$89,全部!$B$2:$B$89,$A7) -> 1180356
A8: 肠神经/消化道 | B8: =COUNTIFS(全部!$A$2:$A$89,"人 Human",全部!$B$2:$B$89,$A8) -> 22 | C8: =COUNTIFS(全部!$A$2:$A$89,"鼠 Mouse",全部!$B$2:$B$89,$A8) -> 4 | D8: =COUNTIFS(全部!$A$2:$A$89,"人鼠 Human;Mouse",全部!$B$2:$B$89,$A8) -> 1 | E8: =SUM(B8:D8) -> 27 | F8: =SUMIFS(全部!$R$2:$R$89,全部!$B$2:$B$89,$A8) -> 9404410
A9: 皮肤 | B9: =COUNTIFS(全部!$A$2:$A$89,"人 Human",全部!$B$2:$B$89,$A9) -> 4 | C9: =COUNTIFS(全部!$A$2:$A$89,"鼠 Mouse",全部!$B$2:$B$89,$A9) -> 1 | D9: =COUNTIFS(全部!$A$2:$A$89,"人鼠 Human;Mouse",全部!$B$2:$B$89,$A9) -> 0 | E9: =SUM(B9:D9) -> 5 | F9: =SUMIFS(全部!$R$2:$R$89,全部!$B$2:$B$89,$A9) -> 710597
A10: 心血管 | B10: =COUNTIFS(全部!$A$2:$A$89,"人 Human",全部!$B$2:$B$89,$A10) -> 8 | C10: =COUNTIFS(全部!$A$2:$A$89,"鼠 Mouse",全部!$B$2:$B$89,$A10) -> 1 | D10: =COUNTIFS(全部!$A$2:$A$89,"人鼠 Human;Mouse",全部!$B$2:$B$89,$A10) -> 0 | E10: =SUM(B10:D10) -> 9 | F10: =SUMIFS(全部!$R$2:$R$89,全部!$B$2:$B$89,$A10) -> 1868493
A11: 呼吸系统 | B11: =COUNTIFS(全部!$A$2:$A$89,"人 Human",全部!$B$2:$B$89,$A11) -> 17 | C11: =COUNTIFS(全部!$A$2:$A$89,"鼠 Mouse",全部!$B$2:$B$89,$A11) -> 0 | D11: =COUNTIFS(全部!$A$2:$A$89,"人鼠 Human;Mouse",全部!$B$2:$B$89,$A11) -> 0 | E11: =SUM(B11:D11) -> 17 | F11: =SUMIFS(全部!$R$2:$R$89,全部!$B$2:$B$89,$A11) -> 4444196
A12: 泌尿系统 | B12: =COUNTIFS(全部!$A$2:$A$89,"人 Human",全部!$B$2:$B$89,$A12) -> 3 | C12: =COUNTIFS(全部!$A$2:$A$89,"鼠 Mouse",全部!$B$2:$B$89,$A12) -> 1 | D12: =COUNTIFS(全部!$A$2:$A$89,"人鼠 Human;Mouse",全部!$B$2:$B$89,$A12) -> 0 | E12: =SUM(B12:D12) -> 4 | F12: =SUMIFS(全部!$R$2:$R$89,全部!$B$2:$B$89,$A12) -> 430619
A13: 生殖/乳腺 | B13: =COUNTIFS(全部!$A$2:$A$89,"人 Human",全部!$B$2:$B$89,$A13) -> 3 | C13: =COUNTIFS(全部!$A$2:$A$89,"鼠 Mouse",全部!$B$2:$B$89,$A13) -> 1 | D13: =COUNTIFS(全部!$A$2:$A$89,"人鼠 Human;Mouse",全部!$B$2:$B$89,$A13) -> 0 | E13: =SUM(B13:D13) -> 4 | F13: =SUMIFS(全部!$R$2:$R$89,全部!$B$2:$B$89,$A13) -> 323767
A14: 内分泌/胰岛 | B14: =COUNTIFS(全部!$A$2:$A$89,"人 Human",全部!$B$2:$B$89,$A14) -> 2 | C14: =COUNTIFS(全部!$A$2:$A$89,"鼠 Mouse",全部!$B$2:$B$89,$A14) -> 1 | D14: =COUNTIFS(全部!$A$2:$A$89,"人鼠 Human;Mouse",全部!$B$2:$B$89,$A14) -> 0 | E14: =SUM(B14:D14) -> 3 | F14: =SUMIFS(全部!$R$2:$R$89,全部!$B$2:$B$89,$A14) -> 550218
A15: 肌肉骨骼 | B15: =COUNTIFS(全部!$A$2:$A$89,"人 Human",全部!$B$2:$B$89,$A15) -> 1 | C15: =COUNTIFS(全部!$A$2:$A$89,"鼠 Mouse",全部!$B$2:$B$89,$A15) -> 1 | D15: =COUNTIFS(全部!$A$2:$A$89,"人鼠 Human;Mouse",全部!$B$2:$B$89,$A15) -> 0 | E15: =SUM(B15:D15) -> 2 | F15: =SUMIFS(全部!$R$2:$R$89,全部!$B$2:$B$89,$A15) -> 285849
A16: 口腔牙齿 | B16: =COUNTIFS(全部!$A$2:$A$89,"人 Human",全部!$B$2:$B$89,$A16) -> 1 | C16: =COUNTIFS(全部!$A$2:$A$89,"鼠 Mouse",全部!$B$2:$B$89,$A16) -> 0 | D16: =COUNTIFS(全部!$A$2:$A$89,"人鼠 Human;Mouse",全部!$B$2:$B$89,$A16) -> 0 | E16: =SUM(B16:D16) -> 1 | F16: =SUMIFS(全部!$R$2:$R$89,全部!$B$2:$B$89,$A16) -> 6560
A17: 肝胆 | B17: =COUNTIFS(全部!$A$2:$A$89,"人 Human",全部!$B$2:$B$89,$A17) -> 2 | C17: =COUNTIFS(全部!$A$2:$A$89,"鼠 Mouse",全部!$B$2:$B$89,$A17) -> 0 | D17: =COUNTIFS(全部!$A$2:$A$89,"人鼠 Human;Mouse",全部!$B$2:$B$89,$A17) -> 0 | E17: =SUM(B17:D17) -> 2 | F17: =SUMIFS(全部!$R$2:$R$89,全部!$B$2:$B$89,$A17) -> 79368
A18: 淋巴/免疫/血液 | B18: =COUNTIFS(全部!$A$2:$A$89,"人 Human",全部!$B$2:$B$89,$A18) -> 2 | C18: =COUNTIFS(全部!$A$2:$A$89,"鼠 Mouse",全部!$B$2:$B$89,$A18) -> 0 | D18: =COUNTIFS(全部!$A$2:$A$89,"人鼠 Human;Mouse",全部!$B$2:$B$89,$A18) -> 0 | E18: =SUM(B18:D18) -> 2 | F18: =SUMIFS(全部!$R$2:$R$89,全部!$B$2:$B$89,$A18) -> 475847
... A20: 多器官图谱/全身 | B20: =COUNTIFS(全部!$A$2:$A$89,"人 Human",全部!$B$2:$B$89,$A20) -> 3 | C20: =COUNTIFS(全部!$A$2:$A$89,"鼠 Mouse",全部!$B$2:$B$89,$A20) -> 2 | D20: =COUNTIFS(全部!$A$2:$A$89,"人鼠 Human;Mouse",全部!$B$2:$B$89,$A20) -> 0 | E20: =SUM(B20:D20) -> 5 | F20: =SUMIFS(全部!$R$2:$R$89,全部!$B$2:$B$89,$A20) -> 2363522
A21: 总计 | B21: =SUM(B7:B20) -> 71 | C21: =SUM(C7:C20) -> 16 | D21: =SUM(D7:D20) -> 1 | E21: =SUM(E7:E20) -> 88 | F21: =SUM(F7:F20) -> 33565209

Sheet 全部
A1: 物种(中文) | B1: 组织系统大类 | C1: 主组织 | D1: Species | E1: 细胞分层 | F1: 分层依据(具体细胞) | G1: 泛化提示 | H1: collection_id | I1: 代表Dataset_ID | J1: Publication_Title | K1: 中文标题 | L1: Year | M1: PMID/DOI | N1: Tissue | O1: Disease | P1: Technology | Q1: 悬浮susp | R1: Cell_Number | S1: 外周相关细胞(规范) | T1: Marker_Genes | U1: Application_Tags | V1: h5ad下载 | W1: collection链接 | X1: 折叠ds数 | Y1: 分工 | Z1: 分工
A2: 人 Human | B2: 周围神经节/神经干 | C2: choroid plexus | D2: Homo sapiens | E2: 待定(泛神经) | F2: — | G2: 含泛glial(疑中枢胶质,慎收) | H2: 59c9ecfe-c47d-4a6a-bab0-895cc0c1942b | I2: CELLxGENE:595c9010-99ec-462d-b6a1-2b2fe5407871 | J2: Dysregulation of brain and choroid plexus cell types in severe COVID-19 | K2: 严重COVID-19中脑和脉络丛细胞类型的失调 | L2: 2024 | M2: 10.1038/s41586-021-03710-0 | N2: choroid plexus | O2: COVID-19|aspiration pneumonia|influenza|malignant pancreatic neoplasm | P2: 10x 3' v3 | Q2: nucleus | R2: 27092 | S2: glial cell | U2: 神经-免疫通讯;炎症 | V2: https://datasets.cellxgene.cziscience.com/6dd04cc1-f4b6-49c4-b34c-56508ea8af8c.h5ad | W2: https://cellxgene.cziscience.com/collections/59c9ecfe-c47d-4a6a-bab0-895cc0c1942b | X2: 1 | Y2: ? | Z2: B
A3: 人 Human | B3: 周围神经节/神经干 | C3: cranial nerve II | D3: Homo sapiens | E3: L2 | F3: L2:Myelinating Schwann cell/Non-myelinating Schwann cell | H3: 05e3d0fc-c9dd-4f14-9163-2b242b3bb5c2 | I3: CELLxGENE:3c364ffe-d599-44d5-a77f-6c5fd7038cf6 | J3: Single cell atlas of the human optic nerve | K3: 人视神经单细胞图谱 | L3: 2025 | M3: not reported in repository metadata | N3: cranial nerve II|optic disc | O3: normal | P3: 10x 3' v3 | Q3: nucleus | R3: 959629 | S3: microglial cell|myelinating Schwann cell|non-myelinating Schwann cell | U3: 针灸作用相关;外周神经再生 | V3: https://datasets.cellxgene.cziscience.com/b27057d6-a6a0-40e8-a4ba-5373a03746d2.h5ad | W3: https://cellxgene.cziscience.com/collections/05e3d0fc-c9dd-4f14-9163-2b242b3bb5c2 | X3: 1 | Y3: ? | Z3: B
A4: 人 Human | B4: 周围神经节/神经干 | C4: dorsal root ganglion | D4: Homo sapiens | E4: L1 | F4: L1:Sensory neuron (DRG) | H4: 741abcf7-af4b-425d-88db-7e0b0d845719 | I4: CELLxGENE:d973ea15-3722-4bc8-a0e8-1d956d26e203 | J4: Single-nucleus transcriptomic analysis of human dorsal root ganglion neurons. | K4: 人背根神经节神经元的单核转录组分析 | L4: 2025 | M4: 10.7554/eLife.71752 | N4: dorsal root ganglion | O4: normal | P4: 10x 3' v2|10x 3' v3 | Q4: nucleus | R4: 1837 | S4: sensory neuron of dorsal root ganglion | U4: 针灸作用相关 | V4: https://datasets.cellxgene.cziscience.com/cf1271ef-08be-46dd-b39e-90c3aa72755e.h5ad | W4: https://cellxgene.cziscience.com/collections/741abcf7-af4b-425d-88db-7e0b0d845719 | X4: 1 | Y4: ? | Z4: B
A5: 人 Human | B5: 肠神经/消化道 | C5: ascending colon | D5: Homo sapiens | E5: L1;L2;L4 | F5: L1:Afferent neuron/Enteric neuron/Inhibitory motor neuron/Interneuron (ENS)/Motor neuron | L2:Enteroglial cell | L4:Enteroendocrine cell/Type EC enteroendocrine cell/Type G enteroendocrine cell/Type X enteroendocrine cell | H5: f11cb29c-b546-4738-9bd8-66ea621a7bd5 | I5: CELLxGENE:19053a82-9c89-4fb8-bd19-d7b1800b0b7b | J5: Single-cell integration reveals metaplasia in inflammatory gut diseases | K5: 单细胞整合揭示炎症性肠道疾病中的化生 | L5: 2025 | M5: 10.1038/s41586-024-07571-1 | N5: ascending colon|body of stomach|buccal mucosa|caecum|caecum epithelium|cecum mucosa|colon|colonic epithelium|colonic mucosa|descending colon|duodenal epithelium|duodenum|epithelium of esophagus|epithelium of rectum|epithelium of small intestine|epithelium of stomach|esophagus|gingiva|ileal epithelium|ileum|ileum lamina propria|intestine|jejunum|labial gland|lamina propria of mucosa of colon|lamina propria of small intestine|mesenteric lymph node|mucosa of sigmoid colon|mucosa of transverse colon|parotid gland|periodontium|pyloric antrum|pylorus|rectosigmoid junction|rectum|sigmoid colon|small intestine|stomach|transverse colon|vermiform appendix | O5: Crohn disease|celiac disease|colorectal cancer|gastric cancer|inflammatory bowel disease|normal|ulcerative colitis | P5: 10x 3' v1|10x 3' v2|10x 3' v3|10x 5' transcription profiling|10x 5' v1|10x 5' v2 | Q5: cell | R5: 1596200 | S5: afferent neuron|enteric neuron|enteroendocrine cell|enteroglial cell|inhibitory motor neuron|interneuron|motor neuron|type EC enteroendocrine cell|type G enteroendocrine cell|type X enteroendocrine cell | U5: 神经-免疫通讯;炎症;伤口修复 | V5: https://datasets.cellxgene.cziscience.com/757945c8-a916-431d-aceb-1afbc80a7c55.h5ad | W5: https://cellxgene.cziscience.com/collections/f11cb29c-b546-4738-9bd8-66ea621a7bd5 | X5: 11 | Y5: ? | Z5: A
A6: 人 Human | B6: 肠神经/消化道 | C6: ascending colon | D6: Homo sapiens | E6: L1;L4 | F6: L1:Inhibitory motor neuron/Interneuron (ENS)/Motor neuron | L4:Enteroendocrine cell/Type D enteroendocrine cell/Type EC enteroendocrine cell/Type L enteroendocrine cell | G6: 含泛glial(疑肠胶质,可能L2) | H6: e33ffcd3-7cbf-4b8c-b0f4-85587ad5019a | I6: CELLxGENE:80a2c5b6-02e7-4fc0-9f12-179f5247c1bc | J6: Cells of the human intestinal tract mapped across space and time | K6: 人类肠道细胞在空间和时间上的图谱 | L6: 2022 | M6: 10.1038/s41586-021-03852-1 | N6: ascending colon|caecum|colon|descending colon|duodenum|ileum|jejunum|large intestine|lymph node|mesenteric lymph node|rectum|sigmoid colon|small intestine|transverse colon|vermiform appendix | O6: Crohn disease|normal | P6: 10x 3' v2|10x 5' v2 | Q6: cell | R6: 428469 | S6: enteroendocrine cell|glial cell|inhibitory motor neuron|interneuron|motor neuron|primary sensory neuron (sensu Teleostei)|type D enteroendocrine cell|type EC enteroendocrine cell|type I enteroendocrine cell|type L enteroendocrine cell|type N enteroendocrine cell | U6: 针灸作用相关;神经-免疫通讯;炎症 | V6: https://datasets.cellxgene.cziscience.com/47ae9727-f767-46b8-9d56-a25ddcd9ae94.h5ad | W6: https://cellxgene.cziscience.com/collections/e33ffcd3-7cbf-4b8c-b0f4-85587ad5019a | X6: 1 | Y6: ? | Z6: A
A7: 人 Human | B7: 肠神经/消化道 | C7: ascending colon | D7: Homo sapiens | E7: L2;L4 | F7: L2:Schwann cell | L4:Enteroendocrine cell of colon | H7: 3a844375-60ea-474b-adf1-98e76928baee | I7: CELLxGENE:05a8c945-bc12-414f-960d-a31943bbcdd1 | J7: Single-cell integration and multi-modal profiling reveals phenotypes and spatial organization of neutrophils in colorectal cancer | K7: 单细胞整合与多模态分析揭示结直肠癌中中性粒细胞的表型及空间组织 | L7: 2026 | M7: 10.1016/j.ccell.2025.12.003 | N7: ascending colon|blood|caecum|caecum epithelium|colon|colonic epithelium|colorectal mucosa|colorectum|descending colon|hepatic cecum|hepatic flexure of colon|left colon|liver|lymph node|mesenteric lymph node|mucosa of transverse colon|rectosigmoid junction|rectum|right colon|sigmoid colon|splenic flexure of colon|transverse colon | O7: colon adenocarcinoma|colon adenocarcinoma || mucinous adenocarcinoma|colon adenoma|colon adenoma || colorectal tubulovillous adenoma|colon adenoma || tubular adenoma|colon carcinoma|colon sessile serrated adenoma/polyp|colorectal adenocarcinoma|colorectal cancer|colorectal neoplasm|colorectal tubulovillous adenoma|hyperplastic polyp|metastasis from malignant tumor of colon|mucinous adenocarcinoma|normal|polyp of colon|rectum adenocarcinoma|tubular adenoma | P7: 10x 3' v1|10x 3' v2|10x 3' v3|10x 5' transcription profiling|10x 5' v1|10x 5' v2|BD Rhapsody Whole Transcriptome Analysis|Fluidigm C1-based SMARTer library preparation|GEXSCOPE technology|Smart-seq2|TruDrop | Q7: cell | R7: 3790266 | S7: Schwann cell|enteroendocrine cell of colon | U7: 神经-免疫通讯;外周神经再生 | V7: https://datasets.cellxgene.cziscience.com/4a8b9568-965e-46b8-a427-baab6bf018e5.h5ad | W7: https://cellxgene.cziscience.com/collections/3a844375-60ea-474b-adf1-98e76928baee | X7: 1 | Y7: ? | Z7: A
A8: 人 Human | B8: 肠神经/消化道 | C8: ascending colon | D8: Homo sapiens | E8: L4 | F8: L4:Enteroendocrine cell of colon/Enteroendocrine cell of small intestine | H8: 64b24fda-6591-4ce1-89e7-33eb6c43ad7b | I8: CELLxGENE:019c7af2-c827-4454-9970-44d5e39ce068 | J8: A proximal-to-distal survey of healthy adult human small intestine and colon epithelium by single-cell transcriptomics | K8: 通过单细胞转录组学对健康成人小肠和结肠上皮进行近端到远端的调查 | L8: 2023 | M8: 10.1016/j.jcmgh.2022.02.007 | N8: ascending colon|descending colon|duodenum|ileum|jejunum|transverse colon | O8: normal | P8: 10x 3' v3 | Q8: cell | R8: 12590 | S8: enteroendocrine cell of colon|enteroendocrine cell of small intestine | U8: general peripheral neurobiology | V8: https://datasets.cellxgene.cziscience.com/487be01d-3df6-417f-83c5-ad2bff5c46e7.h5ad | W8: https://cellxgene.cziscience.com/collections/64b24fda-6591-4ce1-89e7-33eb6c43ad7b | X8: 1 | Y8: ? | Z8: A
A9: 人 Human | B9: 肠神经/消化道 | C9: ascending colon | D9: Homo sapiens | E9: L4 | F9: L4:Enteroendocrine cell | G9: 含泛glial(疑肠胶质,可能L2) | H9: 854c0855-23ad-4362-8b77-6b1639e7a9fc | I9: CELLxGENE:cbec7853-d996-4493-bbf8-5d82857a4e51 | J9: Automatic cell-type harmonization and integration across Human Cell Atlas datasets | K9: 人类细胞图谱数据集间细胞类型的自动协调与整合 | L9: 2024 | M9: 10.1016/j.cell.2023.11.026 | N9: ascending colon|caecum|caecum epithelium|caecum lamina propria|colonic epithelium|descending colon|duodenum|ileum|jejunum|lamina propria of mucosa of colon|large intestine|rectum|sigmoid colon|small intestine|transverse colon|transverse colon epithelium|transverse colon lamina propria|vermiform appendix | O9: normal | P9: 10x 3' v1|10x 3' v2|10x 3' v3|10x 5' v2 | Q9: cell | R9: 263275 | S9: enteroendocrine cell|glial cell | U9: general peripheral neurobiology | V9: https://datasets.cellxgene.cziscience.com/0add1772-6d6e-43e1-8702-93fdf84e4dbc.h5ad | W9: https://cellxgene.cziscience.com/collections/854c0855-23ad-4362-8b77-6b1639e7a9fc | X9: 2 | Y9: ? | Z9: A
A10: 人 Human | B10: 肠神经/消化道 | C10: ascending colon | D10: Homo sapiens | E10: L4 | F10: L4:Intestinal enteroendocrine cell | H10: a48f5033-3438-4550-8574-cdff3263fdfd | I10: CELLxGENE:e40c6272-af77-4a10-9385-62a398884f27 | J10: HTAN VUMC - Differential pre-malignant programs and microenvironment chart distinct paths to malignancy in human colorectal polyps | K10: HTAN VUMC - 差异性的癌前程序与微环境描绘了人类结直肠息肉中通向恶性肿瘤的不同路径 | L10: 2022 | M10: 10.1016/j.cell.2021.11.031 | N10: ascending colon|descending colon|hepatic cecum|hepatic flexure of colon|rectum|sigmoid colon|transverse colon | O10: colon sessile serrated adenoma/polyp|colorectal neoplasm|hyperplastic polyp|normal|tubular adenoma|tubulovillous adenoma | P10: TruDrop | Q10: cell | R10: 65088 | S10: intestinal enteroendocrine cell | U10: general peripheral neurobiology | V10: https://datasets.cellxgene.cziscience.com/9da034b0-de48-47ab-97f6-21b5f2dbd1a4.h5ad | W10: https://cellxgene.cziscience.com/collections/a48f5033-3438-4550-8574-cdff3263fdfd | X10: 2 | Y10: ? | Z10: A
A11: 人 Human | B11: 肠神经/消化道 | C11: blood | D11: Homo sapiens | E11: L4 | F11: L4:Enterochromaffin-like cell/Intestinal enteroendocrine cell | G11: 含泛glial(疑肠胶质,可能L2) | H11: 7f7fdf50-aa0e-4a6f-979c-53655cac9d5d | I11: CELLxGENE:0e5c75da-7bc9-4a2c-83fc-ef1e378bd5f9 | J11: IBDverse: Cell type-resolved genetic variation shapes inflammatory bowel disease risk | K11: IBDverse：细胞类型解析的遗传变异塑造炎症性肠病风险 | L11: 2026 | M11: 10.1038/s41586-026-10627-z | N11: blood|ileum|rectum | O11: Crohn disease|normal | P11: 10x 3' v3 | Q11: cell | R11: 1852681 | S11: enterochromaffin-like cell|glial cell|intestinal enteroendocrine cell | U11: 神经-免疫通讯;炎症 | V11: https://datasets.cellxgene.cziscience.com/e3460364-c300-4616-9923-3a0224894998.h5ad | W11: https://cellxgene.cziscience.com/collections/7f7fdf50-aa0e-4a6f-979c-53655cac9d5d | X11: 1 | Y11: ? | Z11: A
A12: 人 Human | B12: 肠神经/消化道 | C12: body of stomach | D12: Homo sapiens | E12: L1;L4 | F12: L1:Peripheral nervous system neuron | L4:Enteroendocrine cell | G12: 含泛glial(疑肠胶质,可能L2) | H12: dfc09a93-bce0-4c77-893d-e153d1b7f9fa | I12: CELLxGENE:9968be68-ab65-4a38-9e1a-c9b6abece194 | J12: Charting human development using a multi-endodermal organ atlas and organoid models | K12: 利用多内胚层器官图谱与类器官模型描绘人类发育过程 | L12: 2023 | M12: 10.1016/j.cell.2021.04.028 | N12: body of stomach|colon|duodenum|epithelium of trachea|esophagus|ileum|jejunum|liver|lung|pyloric antrum|small intestine|stomach | O12: normal | P12: 10x 3' v2|10x 3' v3 | Q12: cell | R12: 155232 | S12: enteroendocrine cell|glial cell|peripheral nervous system neuron | U12: general peripheral neurobiology | V12: https://datasets.cellxgene.cziscience.com/00b80c9b-8dbd-45c1-8347-51fbe8bd150e.h5ad | W12: https://cellxgene.cziscience.com/collections/dfc09a93-bce0-4c77-893d-e153d1b7f9fa | X12: 2 | Y12: ? | Z12: A
A13: 人 Human | B13: 肠神经/消化道 | C13: body of stomach | D13: Homo sapiens | E13: L4 | F13: L4:Enteroendocrine cell/Type G enteroendocrine cell | H13: a18474f4-ff1e-4864-af69-270b956cee5b | I13: CELLxGENE:7bb64315-9e5a-41b9-9235-59acf9642a3e | J13: Single-cell RNA sequencing unifies developmental programs of Esophageal and Gastric Intestinal Metaplasia | K13: 单细胞RNA测序统一食管与胃肠化生的发育程序 | L13: 2023 | M13: 10.1158/2159-8290.cd-22-0824 | N13: body of stomach|cardia of stomach|colon|duodenum|esophagogastric junction|ileum|lower esophagus|rectum|submucosal esophageal gland | O13: Barrett esophagus|gastric cancer|gastric intestinal metaplasia|gastritis|normal | P13: 10x 3' v2|10x 3' v3|10x 5' v1 | Q13: cell | R13: 293823 | S13: P/D1 enteroendocrine cell|enteroendocrine cell|type G enteroendocrine cell | U13: 神经-免疫通讯 | V13: https://datasets.cellxgene.cziscience.com/3b5ba887-80df-43db-8486-3fc03027a15e.h5ad | W13: https://cellxgene.cziscience.com/collections/a18474f4-ff1e-4864-af69-270b956cee5b | X13: 3 | Y13: ? | Z13: A
A14: 人 Human | B14: 肠神经/消化道 | C14: caecum | D14: Homo sapiens | E14: L4 | F14: L4:Enteroendocrine cell of colon | H14: 1cbfb478-2c7f-4d15-b522-9f74e9fe52a8 | I14: CELLxGENE:829a3cd1-a466-49f1-b2e9-d3f6b7f392e2 | J14: Progressive plasticity during colorectal cancer metastasis | K14: 结直肠癌转移过程中的渐进式可塑性 | L14: 2025 | M14: 10.1038/s41586-024-08560-0 | N14: caecum|chest wall|descending colon|hepatic flexure of colon|liver|lung|peritoneum|rectum|sigmoid colon|transverse colon | O14: colorectal cancer|normal | P14: 10x 3' v3 | Q14: cell | R14: 47107 | S14: enteroendocrine cell of colon | U14: 神经-免疫通讯 | V14: https://datasets.cellxgene.cziscience.com/81bd8922-b69a-45ea-9b2a-032c480c0e37.h5ad | W14: https://cellxgene.cziscience.com/collections/1cbfb478-2c7f-4d15-b522-9f74e9fe52a8 | X14: 3 | Y14: ? | Z14: A
A15: 人 Human | B15: 肠神经/消化道 | C15: caecum epithelium | D15: Homo sapiens | E15: L4 | F15: L4:Enteroendocrine cell | H15: 33d19f34-87f5-455b-8ca5-9023a2e5453d | I15: CELLxGENE:4dd00779-7f73-4f50-89bb-e2d3c6b71b18 | J15: Intra- and Inter-cellular Rewiring of the Human Colon during Ulcerative Colitis | K15: 溃疡性结肠炎期间人结肠的细胞内与细胞间重连 | L15: 2023 | M15: 10.1016/j.cell.2019.06.029 | N15: caecum epithelium|colonic epithelium|transverse colon epithelium | O15: normal | P15: 10x 3' v1|10x 3' v2 | Q15: cell | R15: 34772 | S15: enteroendocrine cell | U15: 神经-免疫通讯;炎症;伤口修复 | V15: https://datasets.cellxgene.cziscience.com/774d77e7-210d-4237-8ca8-8d2bb841a2e4.h5ad | W15: https://cellxgene.cziscience.com/collections/33d19f34-87f5-455b-8ca5-9023a2e5453d | X15: 1 | Y15: ? | Z15: A
A16: 人 Human | B16: 肠神经/消化道 | C16: colon | D16: Homo sapiens | E16: L1;L4 | F16: L1:Enteric neuron | L4:Enteroendocrine cell | H16: 17481d16-ee44-49e5-bcf0-28c0780d8c4a | I16: CELLxGENE:b46237d1-19c6-4af2-9335-9854634bad16 | J16: Single-Cell Sequencing of Developing Human Gut Reveals Transcriptional Links to Childhood Crohn’s Disease | K16: 发育中人类肠道的单细胞测序揭示与儿童克罗恩病的转录关联 | L16: 2022 | M16: 10.1016/j.devcel.2020.11.010 | N16: colon|duodeno-jejunal junction|ileum | O16: normal | P16: 10x 3' v2 | Q16: cell | R16: 62849 | S16: enteric neuron|enteroendocrine cell | U16: 神经-免疫通讯;炎症 | V16: https://datasets.cellxgene.cziscience.com/5cf26393-87e2-4946-8a97-2d42625856a3.h5ad | W16: https://cellxgene.cziscience.com/collections/17481d16-ee44-49e5-bcf0-28c0780d8c4a | X16: 2 | Y16: ? | Z16: A
A17: 人 Human | B17: 肠神经/消化道 | C17: colon | D17: Homo sapiens | E17: L1;L4 | F17: L1:Inhibitory motor neuron/Interneuron (ENS)/Motor neuron | L4:Neuroendocrine cell | G17: 含泛glial(疑肠胶质,可能L2) | H17: 60358420-6055-411d-ba4f-e8ac80682a2e | I17: CELLxGENE:bbd16004-09e8-4b6c-b465-73ff83a52837 | J17: Spatiotemporal analysis of human intestinal development at single-cell resolution | K17: 单细胞分辨率下人类肠道发育的时空分析 | L17: 2021 | M17: 10.1016/j.cell.2020.12.016 | N17: colon|hindgut|ileum | O17: normal | P17: 10x 3' v3 | Q17: cell | R17: 4144 | S17: glial cell|inhibitory motor neuron|interneuron|motor neuron|neuroendocrine cell | U17: general peripheral neurobiology | V17: https://datasets.cellxgene.cziscience.com/a40d9047-5990-4aa1-aac8-2ff55649dab5.h5ad | W17: https://cellxgene.cziscience.com/collections/60358420-6055-411d-ba4f-e8ac80682a2e | X17: 2 | Y17: ? | Z17: A
A18: 人 Human | B18: 肠神经/消化道 | C18: colorectum | D18: Homo sapiens | E18: L2;L4 | F18: L2:Schwann cell | L4:Enteroendocrine cell | H18: 4d82bd8e-8827-410b-8fc7-685b7dd92585 | I18: CELLxGENE:16023185-de21-4c0d-a9c8-73abdd52d142 | J18: Spatially organized multicellular immune hubs in human colorectal cancer | K18: 人类结直肠癌中空间组织的多细胞免疫枢纽 | L18: 2025 | M18: 10.1016/j.cell.2021.08.003 | N18: colorectum | O18: colon adenocarcinoma|normal | P18: 10x 3' v2|10x 3' v3 | Q18: cell | R18: 370115 | S18: Schwann cell|enteroendocrine cell | U18: 神经-免疫通讯;外周神经再生 | V18: https://datasets.cellxgene.cziscience.com/3d1f3641-5755-47e2-b797-10317d33fe32.h5ad | W18: https://cellxgene.cziscience.com/collections/4d82bd8e-8827-410b-8fc7-685b7dd92585 | X18: 3 | Y18: ? | Z18: A
A19: 人 Human | B19: 肠神经/消化道 | C19: duodenum | D19: Homo sapiens | E19: L2;L4 | F19: L2:Enteroglial cell | L4:Enteroendocrine cell of small intestine | H19: e5f58829-1a66-40b5-a624-9046778e74f5 | I19: CELLxGENE:a357414d-2042-4eb5-95f0-c58604a18bdd | J19: Tabula Sapiens | K19: Tabula Sapiens | L19: 2021 | M19: 10.1126/science.abl4896 | N19: duodenum|ileum|jejunum|small intestine | O19: normal | P19: 10x 3' v3|Smart-seq2 | Q19: cell | R19: 42036 | S19: enteroendocrine cell of small intestine|enteroglial cell | U19: general peripheral neurobiology | V19: https://datasets.cellxgene.cziscience.com/6db4dfe6-d421-4287-a9dc-22eaa59be966.h5ad | W19: https://cellxgene.cziscience.com/collections/e5f58829-1a66-40b5-a624-9046778e74f5 | X19: 5 | Y19: ? | Z19: A
A20: 人 Human | B20: 肠神经/消化道 | C20: epithelium of small intestine | D20: Homo sapiens | E20: L4 | F20: L4:Type EC enteroendocrine cell/Type L enteroendocrine cell | H20: 5c868b6f-62c5-4532-9d7f-a346ad4b50a7 | I20: CELLxGENE:fe4b89d5-461e-440c-a5a8-621b37b122c0 | J20: The landscape of immune dysregulation in Crohn’s disease revealed through single-cell transcriptomic profiling in the ileum and colon | K20: 单细胞转录组谱分析揭示克罗恩病回肠与结肠免疫失调的全景 | L20: 2023 | M20: 10.1016/j.immuni.2023.01.002 | N20: epithelium of small intestine|ileal epithelium|ileum|ileum lamina propria|lamina propria of small intestine|small intestine | O20: Crohn disease|normal | P20: 10x 3' v2|10x 3' v3 | Q20: cell | R20: 154136 | S20: type EC enteroendocrine cell|type L enteroendocrine cell | U20: 神经-免疫通讯;炎症 | V20: https://datasets.cellxgene.cziscience.com/6a6b7339-106f-420b-95ae-c8d2d91f9945.h5ad | W20: https://cellxgene.cziscience.com/collections/5c868b6f-62c5-4532-9d7f-a346ad4b50a7 | X20: 4 | Y20: ? | Z20: A
A21: 人 Human | B21: 肠神经/消化道 | C21: ileum | D21: Homo sapiens | E21: L4 | F21: L4:Enteroendocrine cell of colon | H21: ff668d5d-5b3f-49ee-a007-ff0664bf35ec | I21: CELLxGENE:248cf7bf-508b-4c28-a2fd-cabe2ab956aa | J21: Single-cell transcriptome analysis reveals differential nutrient absorption functions in human intestine | K21: 单细胞转录组分析揭示人肠道中差异性的营养吸收功能 | L21: 2022 | M21: 10.1084/jem.20191130 | N21: ileum | O21: normal | P21: 10x 3' v2 | Q21: cell | R21: 5980 | S21: enteroendocrine cell of colon | U21: general peripheral neurobiology | V21: https://datasets.cellxgene.cziscience.com/685f053a-2204-489a-b166-1d0190406be6.h5ad | W21: https://cellxgene.cziscience.com/collections/ff668d5d-5b3f-49ee-a007-ff0664bf35ec | X21: 3 | Y21: ? | Z21: A
A22: 人 Human | B22: 肠神经/消化道 | C22: ileum | D22: Homo sapiens | E22: L4 | F22: L4:Enteroendocrine cell of small intestine | G22: 含泛glial(疑肠胶质,可能L2) | H22: 2b02dff7-e427-4cdc-96fb-c0f354c099aa | I22: CELLxGENE:36c867a7-be10-4e69-9b39-5de12b0af6da | J22: Single-Cell Analysis of Crohn’s Disease Lesions Identifies a Pathogenic Cellular Module Associated with Resistance to Anti-TNF Therapy | K22: 克罗恩病病灶的单细胞分析识别出与抗TNF治疗耐药相关的致病性细胞模块 | L22: 2022 | M22: 10.1016/j.cell.2019.08.008 | N22: ileum | O22: normal | P22: 10x 3' v1|10x 3' v2 | Q22: cell | R22: 32458 | S22: enteroendocrine cell of small intestine|glial cell | U22: 神经-免疫通讯;炎症 | V22: https://datasets.cellxgene.cziscience.com/aa44120b-7b9f-4584-a8a2-0f3aceafc87c.h5ad | W22: https://cellxgene.cziscience.com/collections/2b02dff7-e427-4cdc-96fb-c0f354c099aa | X22: 1 | Y22: ? | Z22: A
A23: 人 Human | B23: 肠神经/消化道 | C23: intestinal mucosa | D23: Homo sapiens | E23: L4 | F23: L4:Enteroendocrine cell | G23: 含泛neuron(肠,待裁定) | H23: f30e0bf7-7b03-44b0-b312-cda799ef0240 | I23: CELLxGENE:51d9716c-50bb-4fd8-8d1e-7d9329969cb7 | J23: iPSC-derived small intestine-on-chip with self-organizing epithelial, mesenchymal and neural cells | K23: iPSC衍生的小肠芯片模型：具有自组织上皮、间充质及神经细胞 | L23: 2024 | M23: 10.1016/j.celrep.2024.114247 | N23: intestinal mucosa | O23: normal | P23: 10x 3' v3 | Q23: cell | R23: 11177 | S23: enteroendocrine cell|neuron | U23: general peripheral neurobiology | V23: https://datasets.cellxgene.cziscience.com/c4bfcccf-6009-4590-a06d-c1443372c6c7.h5ad | W23: https://cellxgene.cziscience.com/collections/f30e0bf7-7b03-44b0-b312-cda799ef0240 | X23: 2 | Y23: ? | Z23: A
A24: 人 Human | B24: 肠神经/消化道 | C24: lamina propria of small intestine | D24: Homo sapiens | E24: L4 | F24: L4:Enteroendocrine cell | G24: 含泛glial(疑肠胶质,可能L2) | H24: a064d795-3b77-44ae-9fb5-beb57c567443 | I24: CELLxGENE:6ceeaa86-9ceb-4582-b390-6d4dd6ff0572 | J24: Pediatric FGID lamina propria of ileum biopsies. | K24: 儿童FGID回肠固有层活检 | L24: 2023 | M24: 10.1101/2021.09.17.21263540 | N24: lamina propria of small intestine | O24: digestive system disorder | P24: 10x 3' v2 | Q24: cell | R24: 89849 | S24: enteroendocrine cell|glial cell | U24: general peripheral neurobiology | V24: https://datasets.cellxgene.cziscience.com/8cf9e6a2-5cd6-4d8e-95bd-b8c54d05e3f1.h5ad | W24: https://cellxgene.cziscience.com/collections/a064d795-3b77-44ae-9fb5-beb57c567443 | X24: 1 | Y24: ? | Z24: A
A25: 人 Human | B25: 肠神经/消化道 | C25: right colon | D25: Homo sapiens | E25: L1 | F25: L1:Neuronal receptor cell | H25: 3b8b7fec-ed65-4483-9579-9f98f5a93a74 | I25: CELLxGENE:5d4415d1-cfcd-4b43-b2b2-138b5afd68af | J25: Epithelium-enriched single cell transcriptomes from the ascending colon of pediatric and adult control subjects | K25: 儿童和成人对照升结肠上皮富集的单细胞转录组 | L25: 2026 | M25: 10.1016/j.jcmgh.2025.101665 | N25: right colon | O25: normal | P25: 10x 3' v3 | Q25: cell | R25: 35957 | S25: neuronal receptor cell | U25: general peripheral neurobiology | V25: https://datasets.cellxgene.cziscience.com/45566c3d-0484-4b2b-858b-8aea1783f21f.h5ad | W25: https://cellxgene.cziscience.com/collections/3b8b7fec-ed65-4483-9579-9f98f5a93a74 | X25: 2 | Y25: ? | Z25: A
A26: 人 Human | B26: 肠神经/消化道 | C26: small intestine | D26: Homo sapiens | E26: L4 | F26: L4:Enteroendocrine cell | G26: 含泛neuron(肠,待裁定) | H26: 7651ac1a-f947-463a-9223-a9e408a41989 | I26: CELLxGENE:3f32121d-126b-4e8d-9f69-d86502d2a1b1 | J26: Insulin is expressed by enteroendocrine cells during human fetal development | K26: 人胎儿发育期间肠内分泌细胞表达胰岛素 | L26: 2023 | M26: 10.1038/s41591-021-01586-1 | N26: small intestine | O26: normal | P26: 10x 3' v2|10x 3' v3 | Q26: cell | R26: 36359 | S26: enteroendocrine cell|neuron | U26: general peripheral neurobiology | V26: https://datasets.cellxgene.cziscience.com/fe96972c-7199-4146-9e03-af518d8916cc.h5ad | W26: https://cellxgene.cziscience.com/collections/7651ac1a-f947-463a-9223-a9e408a41989 | X26: 1 | Y26: ? | Z26: A
A27: 人 Human | B27: 皮肤 | C27: arm skin | D27: Homo sapiens | E27: L2 | F27: L2:Schwann cell | H27: 34f12de7-c5e5-4813-a136-832677f98ac8 | I27: CELLxGENE:e7c5ba7e-4be0-4696-af50-a07d0dc7aac5 | J27: Multi-scale spatial mapping of cell populations across anatomical sites in healthy human skin and basal cell carcinoma | K27: 健康人皮肤和基底细胞癌中跨解剖部位细胞群体的多尺度空间图谱 | L27: 2024 | M27: 10.1073/pnas.2313326120 | N27: arm skin|nose skin|skin of abdomen|skin of cheek|skin of external ear|skin of forehead|skin of temple | O27: basal cell carcinoma|normal | P27: 10x 3' v1|10x 3' v2|10x 3' v3 | Q27: cell | R27: 152189 | S27: Schwann cell | U27: 外周神经再生 | V27: https://datasets.cellxgene.cziscience.com/82515193-f68f-49f1-923e-d10a2b798b42.h5ad | W27: https://cellxgene.cziscience.com/collections/34f12de7-c5e5-4813-a136-832677f98ac8 | X27: 1 | Y27: A | Z27: A
A28: 人 Human | B28: 皮肤 | C28: dermis | D28: Homo sapiens | E28: L2 | F28: L2:Schwann cell | H28: 73f82ac8-15cc-4fcd-87f8-5683723fce7f | I28: CELLxGENE:f0f0d7c4-3bec-428e-9539-c99d36548d96 | J28: Developmental cell programs are co-opted in inflammatory skin disease | K28: 炎症性皮肤病中发育细胞程序被共选利用 | L28: 2024 | M28: 10.1126/science.aba6500 | N28: dermis|skin epidermis | O28: normal | P28: 10x 3' v2 | Q28: cell | R28: 195739 | S28: Schwann cell | U28: 神经-免疫通讯;外周神经再生;炎症 | V28: https://datasets.cellxgene.cziscience.com/f8b5c4f4-7ece-4314-9f49-fc254bbd5c71.h5ad | W28: https://cellxgene.cziscience.com/collections/73f82ac8-15cc-4fcd-87f8-5683723fce7f | X28: 1 | Y28: A | Z28: A
A29: 人 Human | B29: 皮肤 | C29: skin of body | D29: Homo sapiens | E29: L2 | F29: L2:Schwann cell | H29: 5e143645-177c-45b6-952d-48770e29a54b | I29: CELLxGENE:b0ef440b-e303-4ad2-ada8-ce13336280ba | J29: Multi-modal skin atlas identifies a multicellular immune-stromal community associated with altered cornification and specific T cell expansion in atopic dermatitis | K29: 多模态皮肤图谱识别出与特应性皮炎中角质化改变及特定T细胞扩增相关的多细胞免疫-基质群落 | L29: 2026 | M29: 10.1038/s41467-026-69587-7 | N29: skin of body | O29: atopic eczema|normal | P29: 10x 3' v2|10x 3' v3 | Q29: cell | R29: 280518 | S29: Schwann cell | U29: 神经-免疫通讯;外周神经再生 | V29: https://datasets.cellxgene.cziscience.com/e046218f-6a66-46f9-a91c-7f26b4ee00c2.h5ad | W29: https://cellxgene.cziscience.com/collections/5e143645-177c-45b6-952d-48770e29a54b | X29: 1 | Y29: A | Z29: A
A30: 人 Human | B30: 皮肤 | C30: subcutaneous abdominal adipose tissue | D30: Homo sapiens | E30: L2 | F30: L2:Schwann cell | H30: 6b701826-37bb-4356-9792-ff41fc4c3161 | I30: CELLxGENE:9d8e5dca-03a3-457d-b7fb-844c75735c83 | J30: Single-Nucleus Analysis of Human White Adipose Tissue Reveals Adipocyte Subsets with Distinct Metabolic Profiles | K30: 人白色脂肪组织单细胞核分析揭示具有不同代谢特征的脂肪细胞亚群 | L30: 2023 | M30: 10.1101/2025.09.14.673351 | N30: subcutaneous abdominal adipose tissue|visceral abdominal adipose tissue | O30: normal | P30: 10x 3' v3 | Q30: nucleus | R30: 72335 | S30: Schwann cell|neuron associated cell | U30: 外周神经再生 | V30: https://datasets.cellxgene.cziscience.com/3d0f967f-ad82-4470-a46d-6d156ad13e42.h5ad | W30: https://cellxgene.cziscience.com/collections/6b701826-37bb-4356-9792-ff41fc4c3161 | X30: 1 | Y30: A | Z30: A
A31: 人 Human | B31: 心血管 | C31: apex of heart | D31: Homo sapiens | E31: L1 | F31: L1:Cardiac neuron | H31: 20eea6c8-9d64-42c9-9b6f-c11b5249e0e9 | I31: CELLxGENE:2e9d2f32-4cfb-49b5-b990-cbf4c241214e | J31: Single-cell genomics improves the discovery of risk variants and genes of atrial fibrillation | K31: 单细胞基因组学改进心房颤动风险变异和基因的发现 | L31: 2024 | M31: 10.1038/s41467-023-40505-5 | N31: apex of heart|heart left ventricle|heart right ventricle|interventricular septum | O31: normal | P31: 10x 3' v3 | Q31: nucleus | R31: 49359 | S31: cardiac neuron | U31: general peripheral neurobiology | V31: https://datasets.cellxgene.cziscience.com/f35a8c3f-b3a0-4373-a4cd-c937db7f7ec2.h5ad | W31: https://cellxgene.cziscience.com/collections/20eea6c8-9d64-42c9-9b6f-c11b5249e0e9 | X31: 1 | Y31: A | Z31: A
A32: 人 Human | B32: 心血管 | C32: apex of heart | D32: Homo sapiens | E32: L1 | F32: L1:Cardiac neuron | H32: e75342a8-0f3b-4ec5-8ee1-245a23e0f7cb | I32: CELLxGENE:65badd7a-9262-4fd1-9ce2-eb5dc0ca8039 | J32: Pathogenic variants damage cell composition and single cell transcription in cardiomyopathies | K32: 致病性变异损害心肌病中的细胞组成与单细胞转录 | L32: 2022 | M32: 10.1126/science.abo1984 | N32: apex of heart|heart left ventricle|heart right ventricle|interventricular septum | O32: arrhythmogenic right ventricular cardiomyopathy|dilated cardiomyopathy|non-compaction cardiomyopathy|normal | P32: 10x 3' v2|10x 3' v3 | Q32: nucleus | R32: 881081 | S32: cardiac neuron | U32: general peripheral neurobiology | V32: https://datasets.cellxgene.cziscience.com/6d0b8b8a-2b22-4578-b8ee-8ca4ab893594.h5ad | W32: https://cellxgene.cziscience.com/collections/e75342a8-0f3b-4ec5-8ee1-245a23e0f7cb | X32: 2 | Y32: A | Z32: A
A33: 人 Human | B33: 心血管 | C33: apex of heart | D33: Homo sapiens | E33: L1 | F33: L1:Cardiac neuron | H33: 328d71f0-0ed7-4518-966f-be6bd0797324 | I33: CELLxGENE:fe7aae33-6f7c-41a5-8d29-9996a9ddf1ab | J33: The cellular and molecular cardiac tissue responses in human inflammatory cardiomyopathies after SARS-CoV-2 infection and COVID-19 vaccination | K33: SARS-CoV-2感染和COVID-19疫苗接种后人炎症性心肌病的心脏细胞与分子组织反应 | L33: 2025 | M33: 10.1038/s44161-025-00612-6 | N33: apex of heart|heart left ventricle | O33: myocarditis|normal | P33: 10x 3' v2|10x 3' v3 | Q33: nucleus | R33: 205596 | S33: cardiac neuron | U33: 神经-免疫通讯;炎症 | V33: https://datasets.cellxgene.cziscience.com/5ca4319d-488f-444d-b383-e909fe0783d4.h5ad | W33: https://cellxgene.cziscience.com/collections/328d71f0-0ed7-4518-966f-be6bd0797324 | X33: 1 | Y33: A | Z33: A
A34: 人 Human | B34: 心血管 | C34: apex of heart | D34: Homo sapiens | E34: 待定(泛神经) | F34: — | G34: 含泛neuron(器官图谱→疑中枢/噪声,待裁定) | H34: 43b45a20-a969-49ac-a8e8-8c84b211bd01 | I34: CELLxGENE:5500c673-1610-40a0-86d9-64d987ae50e6 | J34: Integrated adult and foetal heart single-cell RNA sequencing | K34: 整合成人与胎儿心脏单细胞RNA测序 | L34: 2023 | M34: 10.1038/s44161-022-00183-w | N34: apex of heart|basal zone of heart|heart left ventricle|heart right ventricle|interventricular septum|left cardiac atrium|right cardiac atrium | O34: normal | P34: 10x 3' v2|10x 3' v3 | Q34: cell|nucleus | R34: 60668 | S34: neuron | U34: general peripheral neurobiology | V34: https://datasets.cellxgene.cziscience.com/85f6cdae-10c2-4c97-8a95-cf03f87ecd2e.h5ad | W34: https://cellxgene.cziscience.com/collections/43b45a20-a969-49ac-a8e8-8c84b211bd01 | X34: 1 | Y34: A | Z34: A
A35: 人 Human | B35: 心血管 | C35: apical region of left ventricle | D35: Homo sapiens | E35: 待定(泛神经) | F35: — | G35: 含泛neuron(器官图谱→疑中枢/噪声,待裁定) | H35: 68e7e5b7-4dc9-4609-832e-7656aa6182ba | I35: CELLxGENE:99e317c0-1fab-4f73-b511-859e752fd1c3 | J35: Sex-Specific Control of Human Heart Maturation by the Progesterone Receptor | K35: 孕激素受体对人类心脏成熟的性别特异性调控 | L35: 2024 | M35: 10.1161/CIRCULATIONAHA.120.051921 | N35: apical region of left ventricle | O35: normal | P35: 10x 3' v3 | Q35: nucleus | R35: 51176 | S35: neuron | U35: general peripheral neurobiology | V35: https://datasets.cellxgene.cziscience.com/59c9aa5c-ee73-4252-b149-5cb011f924b1.h5ad | W35: https://cellxgene.cziscience.com/collections/68e7e5b7-4dc9-4609-832e-7656aa6182ba | X35: 1 | Y35: A | Z35: A
A36: 人 Human | B36: 心血管 | C36: heart | D36: Homo sapiens | E36: 待定(泛神经) | F36: — | G36: 含泛neuron(器官图谱→疑中枢/噪声,待裁定) | H36: 9c9ce98a-6b02-4262-9407-1ebb2de31f63 | I36: CELLxGENE:9928ad5f-6afd-4fb0-89b0-6690e2a2ce25 | J36: Integrated multi-omic characterization of congenital heart disease | K36: 先天性心脏病的整合多组学特征分析 | L36: 2026 | M36: 10.1038/s41586-022-04989-3 | N36: heart | O36: congenital heart disease|dilated cardiomyopathy|hypertrophic cardiomyopathy|hypoplastic left heart syndrome|tetralogy of fallot | P36: 10x 3' v3 | Q36: nucleus | R36: 157293 | S36: neuron | U36: general peripheral neurobiology | V36: https://datasets.cellxgene.cziscience.com/beb6ae0c-c47b-4a8d-9f8d-39a43f5853bd.h5ad | W36: https://cellxgene.cziscience.com/collections/9c9ce98a-6b02-4262-9407-1ebb2de31f63 | X36: 1 | Y36: A | Z36: A
A37: 人 Human | B37: 心血管 | C37: heart left ventricle | D37: Homo sapiens | E37: L1 | F37: L1:Neuronal receptor cell | H37: 8191c283-0816-424b-9b61-c3e1d6258a77 | I37: CELLxGENE:1c739a3e-c3f5-49d5-98e0-73975e751201 | J37: Spatial multi-omic map of human myocardial infarction | K37: 人类心肌梗死的空间多组学图谱 | L37: 2022 | M37: 10.1038/s41586-022-05060-x | N37: heart left ventricle | O37: myocardial infarction|normal | P37: 10x 3' v3 | Q37: nucleus | R37: 191795 | S37: neuronal receptor cell | U37: 针灸作用相关 | V37: https://datasets.cellxgene.cziscience.com/4780eb7d-4c7c-4630-8705-471f0de8e27a.h5ad | W37: https://cellxgene.cziscience.com/collections/8191c283-0816-424b-9b61-c3e1d6258a77 | X37: 3 | Y37: A | Z37: A
A38: 人 Human | B38: 心血管 | C38: right atrium auricular region | D38: Homo sapiens | E38: L2 | F38: L2:Schwann cell | G38: 含泛neuron(器官图谱→疑中枢/噪声,待裁定) | H38: 8c782494-01ed-491b-97b9-6f0d3b76c676 | I38: CELLxGENE:8f4f8502-9170-4ac2-9707-3b6985ebfe5f | J38: Transcriptomic and spatial dissection of human ex vivo right atrial tissue reveals proinflammatory microvascular changes in ischemic heart disease | K38: 人类离体右心房组织的转录组与空间解析揭示缺血性心脏病中的促炎性微血管变化 | L38: 2024 | M38: 10.1016/j.xcrm.2024.101556 | N38: right atrium auricular region | O38: heart failure|heart valve disorder|myocardial ischemia|normal | P38: 10x 3' v3 | Q38: nucleus | R38: 221756 | S38: Schwann cell|neuron | U38: 针灸作用相关;神经-免疫通讯;外周神经再生;炎症 | V38: https://datasets.cellxgene.cziscience.com/86094298-00c2-4d09-b11d-342c5aa1f951.h5ad | W38: https://cellxgene.cziscience.com/collections/8c782494-01ed-491b-97b9-6f0d3b76c676 | X38: 2 | Y38: A | Z38: A
A39: 人 Human | B39: 呼吸系统 | C39: blood | D39: Homo sapiens | E39: L4 | F39: L4:Pulmonary neuroendocrine cell | H39: 5d445965-6f1a-4b68-ba3a-b8f765155d3a | I39: CELLxGENE:8c42cfd0-0b0a-46d5-910c-fc833d83c45e | J39: A molecular cell atlas of the human lung from single cell RNA sequencing | K39: 单细胞RNA测序揭示的人类肺分子细胞图谱 | L39: 2020 | M39: 10.1038/s41586-020-2922-4 | N39: blood|lung | O39: normal | P39: 10x 3' v2 | Q39: cell | R39: 65662 | S39: pulmonary neuroendocrine cell | U39: general peripheral neurobiology | V39: https://datasets.cellxgene.cziscience.com/f5568ea3-c249-4e4e-91f8-46abc30a5612.h5ad | W39: https://cellxgene.cziscience.com/collections/5d445965-6f1a-4b68-ba3a-b8f765155d3a | X39: 2 | Y39: B | Z39: B
A40: 人 Human | B40: 呼吸系统 | C40: bronchus | D40: Homo sapiens | E40: L2;L4 | F40: L2:Myelinating Schwann cell/Non-myelinating Schwann cell | L4:Neuroendocrine cell | H40: c1241244-b22d-483d-875b-75699efb9f3c | I40: CELLxGENE:093d3bfe-6f0f-4ac0-a7a1-829f94d0a49f | J40: A spatially resolved atlas of the human lung characterizes a gland-associated immune niche | K40: 人类肺部的空间分辨图谱刻画了一个腺体相关的免疫微环境 | L40: 2024 | M40: 10.1038/s41588-022-01243-4 | N40: bronchus|lower lobe of left lung|lung|trachea|upper lobe of left lung | O40: normal | P40: 10x 3' v2|10x 3' v3|10x 5' transcription profiling | Q40: cell|nucleus | R40: 193108 | S40: myelinating Schwann cell|neuroendocrine cell|non-myelinating Schwann cell | U40: 神经-免疫通讯;外周神经再生 | V40: https://datasets.cellxgene.cziscience.com/dea9f35e-1be6-4240-919d-7eb2f471cbe9.h5ad | W40: https://cellxgene.cziscience.com/collections/c1241244-b22d-483d-875b-75699efb9f3c | X40: 3 | Y40: B | Z40: B
...

Sheet 人 Human
A1: 物种(中文) | B1: 组织系统大类 | C1: 主组织 | D1: Species | E1: 细胞分层 | F1: 分层依据(具体细胞) | G1: 泛化提示 | H1: collection_id | I1: 代表Dataset_ID | J1: Publication_Title | K1: 中文标题 | L1: Year | M1: PMID/DOI | N1: Tissue | O1: Disease | P1: Technology | Q1: 悬浮susp | R1: Cell_Number | S1: 外周相关细胞(规范) | T1: Marker_Genes | U1: Application_Tags | V1: h5ad下载 | W1: collection链接 | X1: 折叠ds数
A2: 人 Human | B2: 周围神经节/神经干 | C2: choroid plexus | D2: Homo sapiens | E2: 待定(泛神经) | F2: — | G2: 含泛glial(疑中枢胶质,慎收) | H2: 59c9ecfe-c47d-4a6a-bab0-895cc0c1942b | I2: CELLxGENE:595c9010-99ec-462d-b6a1-2b2fe5407871 | J2: Dysregulation of brain and choroid plexus cell types in severe COVID-19 | K2: 严重COVID-19中脑和脉络丛细胞类型的失调 | L2: 2024 | M2: 10.1038/s41586-021-03710-0 | N2: choroid plexus | O2: COVID-19|aspiration pneumonia|influenza|malignant pancreatic neoplasm | P2: 10x 3' v3 | Q2: nucleus | R2: 27092 | S2: glial cell | T2: SOX10;PLP1;S100B;GFRA3;FABP7 | U2: 神经-免疫通讯;炎症 | V2: https://datasets.cellxgene.cziscience.com/6dd04cc1-f4b6-49c4-b34c-56508ea8af8c.h5ad | W2: https://cellxgene.cziscience.com/collections/59c9ecfe-c47d-4a6a-bab0-895cc0c1942b | X2: 1
A3: 人 Human | B3: 周围神经节/神经干 | C3: cranial nerve II | D3: Homo sapiens | E3: L2 | F3: L2:Myelinating Schwann cell/Non-myelinating Schwann cell | H3: 05e3d0fc-c9dd-4f14-9163-2b242b3bb5c2 | I3: CELLxGENE:3c364ffe-d599-44d5-a77f-6c5fd7038cf6 | J3: Single cell atlas of the human optic nerve | K3: 人视神经单细胞图谱 | L3: 2025 | M3: not reported in repository metadata | N3: cranial nerve II|optic disc | O3: normal | P3: 10x 3' v3 | Q3: nucleus | R3: 959629 | S3: microglial cell|myelinating Schwann cell|non-myelinating Schwann cell | T3: SOX10;MPZ;PLP1;MBP;PMP22 | U3: 针灸作用相关;外周神经再生 | V3: https://datasets.cellxgene.cziscience.com/b27057d6-a6a0-40e8-a4ba-5373a03746d2.h5ad | W3: https://cellxgene.cziscience.com/collections/05e3d0fc-c9dd-4f14-9163-2b242b3bb5c2 | X3: 1
A4: 人 Human | B4: 周围神经节/神经干 | C4: dorsal root ganglion | D4: Homo sapiens | E4: L1 | F4: L1:Sensory neuron (DRG) | H4: 741abcf7-af4b-425d-88db-7e0b0d845719 | I4: CELLxGENE:d973ea15-3722-4bc8-a0e8-1d956d26e203 | J4: Single-nucleus transcriptomic analysis of human dorsal root ganglion neurons. | K4: 人背根神经节神经元的单核转录组分析 | L4: 2025 | M4: 10.7554/eLife.71752 | N4: dorsal root ganglion | O4: normal | P4: 10x 3' v2|10x 3' v3 | Q4: nucleus | R4: 1837 | S4: sensory neuron of dorsal root ganglion | T4: RBFOX3;TUBB3;SNAP25;PRPH;PHOX2B | U4: 针灸作用相关 | V4: https://datasets.cellxgene.cziscience.com/cf1271ef-08be-46dd-b39e-90c3aa72755e.h5ad | W4: https://cellxgene.cziscience.com/collections/741abcf7-af4b-425d-88db-7e0b0d845719 | X4: 1
A5: 人 Human | B5: 肠神经/消化道 | C5: ascending colon | D5: Homo sapiens | E5: L1;L2;L4 | F5: L1:Afferent neuron/Enteric neuron/Inhibitory motor neuron/Interneuron (ENS)/Motor neuron | L2:Enteroglial cell | L4:Enteroendocrine cell/Type EC enteroendocrine cell/Type G enteroendocrine cell/Type X enteroendocrine cell | H5: f11cb29c-b546-4738-9bd8-66ea621a7bd5 | I5: CELLxGENE:19053a82-9c89-4fb8-bd19-d7b1800b0b7b | J5: Single-cell integration reveals metaplasia in inflammatory gut diseases | K5: 单细胞整合揭示炎症性肠道疾病中的化生 | L5: 2025 | M5: 10.1038/s41586-024-07571-1 | N5: ascending colon|body of stomach|buccal mucosa|caecum|caecum epithelium|cecum mucosa|colon|colonic epithelium|colonic mucosa|descending colon|duodenal epithelium|duodenum|epithelium of esophagus|epithelium of rectum|epithelium of small intestine|epithelium of stomach|esophagus|gingiva|ileal epithelium|ileum|ileum lamina propria|intestine|jejunum|labial gland|lamina propria of mucosa of colon|lamina propria of small intestine|mesenteric lymph node|mucosa of sigmoid colon|mucosa of transverse colon|parotid gland|periodontium|pyloric antrum|pylorus|rectosigmoid junction|rectum|sigmoid colon|small intestine|stomach|transverse colon|vermiform appendix | O5: Crohn disease|celiac disease|colorectal cancer|gastric cancer|inflammatory bowel disease|normal|ulcerative colitis | P5: 10x 3' v1|10x 3' v2|10x 3' v3|10x 5' transcription profiling|10x 5' v1|10x 5' v2 | Q5: cell | R5: 1596200 | S5: afferent neuron|enteric neuron|enteroendocrine cell|enteroglial cell|inhibitory motor neuron|interneuron|motor neuron|type EC enteroendocrine cell|type G enteroendocrine cell|type X enteroendocrine cell | T5: SOX10;PLP1;S100B;GFRA3;FABP7 | U5: 神经-免疫通讯;炎症;伤口修复 | V5: https://datasets.cellxgene.cziscience.com/757945c8-a916-431d-aceb-1afbc80a7c55.h5ad | W5: https://cellxgene.cziscience.com/collections/f11cb29c-b546-4738-9bd8-66ea621a7bd5 | X5: 11
A6: 人 Human | B6: 肠神经/消化道 | C6: ascending colon | D6: Homo sapiens | E6: L1;L4 | F6: L1:Inhibitory motor neuron/Interneuron (ENS)/Motor neuron | L4:Enteroendocrine cell/Type D enteroendocrine cell/Type EC enteroendocrine cell/Type L enteroendocrine cell | G6: 含泛glial(疑肠胶质,可能L2) | H6: e33ffcd3-7cbf-4b8c-b0f4-85587ad5019a | I6: CELLxGENE:80a2c5b6-02e7-4fc0-9f12-179f5247c1bc | J6: Cells of the human intestinal tract mapped across space and time | K6: 人类肠道细胞在空间和时间上的图谱 | L6: 2022 | M6: 10.1038/s41586-021-03852-1 | N6: ascending colon|caecum|colon|descending colon|duodenum|ileum|jejunum|large intestine|lymph node|mesenteric lymph node|rectum|sigmoid colon|small intestine|transverse colon|vermiform appendix | O6: Crohn disease|normal | P6: 10x 3' v2|10x 5' v2 | Q6: cell | R6: 428469 | S6: enteroendocrine cell|glial cell|inhibitory motor neuron|interneuron|motor neuron|primary sensory neuron (sensu Teleostei)|type D enteroendocrine cell|type EC enteroendocrine cell|type I enteroendocrine cell|type L enteroendocrine cell|type N enteroendocrine cell | T6: SOX10;PLP1;S100B;GFRA3;FABP7 | U6: 针灸作用相关;神经-免疫通讯;炎症 | V6: https://datasets.cellxgene.cziscience.com/47ae9727-f767-46b8-9d56-a25ddcd9ae94.h5ad | W6: https://cellxgene.cziscience.com/collections/e33ffcd3-7cbf-4b8c-b0f4-85587ad5019a | X6: 1
A7: 人 Human | B7: 肠神经/消化道 | C7: ascending colon | D7: Homo sapiens | E7: L2;L4 | F7: L2:Schwann cell | L4:Enteroendocrine cell of colon | H7: 3a844375-60ea-474b-adf1-98e76928baee | I7: CELLxGENE:05a8c945-bc12-414f-960d-a31943bbcdd1 | J7: Single-cell integration and multi-modal profiling reveals phenotypes and spatial organization of neutrophils in colorectal cancer | K7: 单细胞整合与多模态分析揭示结直肠癌中中性粒细胞的表型及空间组织 | L7: 2026 | M7: 10.1016/j.ccell.2025.12.003 | N7: ascending colon|blood|caecum|caecum epithelium|colon|colonic epithelium|colorectal mucosa|colorectum|descending colon|hepatic cecum|hepatic flexure of colon|left colon|liver|lymph node|mesenteric lymph node|mucosa of transverse colon|rectosigmoid junction|rectum|right colon|sigmoid colon|splenic flexure of colon|transverse colon | O7: colon adenocarcinoma|colon adenocarcinoma || mucinous adenocarcinoma|colon adenoma|colon adenoma || colorectal tubulovillous adenoma|colon adenoma || tubular adenoma|colon carcinoma|colon sessile serrated adenoma/polyp|colorectal adenocarcinoma|colorectal cancer|colorectal neoplasm|colorectal tubulovillous adenoma|hyperplastic polyp|metastasis from malignant tumor of colon|mucinous adenocarcinoma|normal|polyp of colon|rectum adenocarcinoma|tubular adenoma | P7: 10x 3' v1|10x 3' v2|10x 3' v3|10x 5' transcription profiling|10x 5' v1|10x 5' v2|BD Rhapsody Whole Transcriptome Analysis|Fluidigm C1-based SMARTer library preparation|GEXSCOPE technology|Smart-seq2|TruDrop | Q7: cell | R7: 3790266 | S7: Schwann cell|enteroendocrine cell of colon | T7: SOX10;MPZ;PLP1;MBP;PMP22 | U7: 神经-免疫通讯;外周神经再生 | V7: https://datasets.cellxgene.cziscience.com/4a8b9568-965e-46b8-a427-baab6bf018e5.h5ad | W7: https://cellxgene.cziscience.com/collections/3a844375-60ea-474b-adf1-98e76928baee | X7: 1
A8: 人 Human | B8: 肠神经/消化道 | C8: ascending colon | D8: Homo sapiens | E8: L4 | F8: L4:Enteroendocrine cell of colon/Enteroendocrine cell of small intestine | H8: 64b24fda-6591-4ce1-89e7-33eb6c43ad7b | I8: CELLxGENE:019c7af2-c827-4454-9970-44d5e39ce068 | J8: A proximal-to-distal survey of healthy adult human small intestine and colon epithelium by single-cell transcriptomics | K8: 通过单细胞转录组学对健康成人小肠和结肠上皮进行近端到远端的调查 | L8: 2023 | M8: 10.1016/j.jcmgh.2022.02.007 | N8: ascending colon|descending colon|duodenum|ileum|jejunum|transverse colon | O8: normal | P8: 10x 3' v3 | Q8: cell | R8: 12590 | S8: enteroendocrine cell of colon|enteroendocrine cell of small intestine | T8: CHGA;CHGB;NEUROD1;PAX6;GCG | U8: general peripheral neurobiology | V8: https://datasets.cellxgene.cziscience.com/487be01d-3df6-417f-83c5-ad2bff5c46e7.h5ad | W8: https://cellxgene.cziscience.com/collections/64b24fda-6591-4ce1-89e7-33eb6c43ad7b | X8: 1
A9: 人 Human | B9: 肠神经/消化道 | C9: ascending colon | D9: Homo sapiens | E9: L4 | F9: L4:Enteroendocrine cell | G9: 含泛glial(疑肠胶质,可能L2) | H9: 854c0855-23ad-4362-8b77-6b1639e7a9fc | I9: CELLxGENE:cbec7853-d996-4493-bbf8-5d82857a4e51 | J9: Automatic cell-type harmonization and integration across Human Cell Atlas datasets | K9: 人类细胞图谱数据集间细胞类型的自动协调与整合 | L9: 2024 | M9: 10.1016/j.cell.2023.11.026 | N9: ascending colon|caecum|caecum epithelium|caecum lamina propria|colonic epithelium|descending colon|duodenum|ileum|jejunum|lamina propria of mucosa of colon|large intestine|rectum|sigmoid colon|small intestine|transverse colon|transverse colon epithelium|transverse colon lamina propria|vermiform appendix | O9: normal | P9: 10x 3' v1|10x 3' v2|10x 3' v3|10x 5' v2 | Q9: cell | R9: 263275 | S9: enteroendocrine cell|glial cell | T9: SOX10;PLP1;S100B;GFRA3;FABP7 | U9: general peripheral neurobiology | V9: https://datasets.cellxgene.cziscience.com/0add1772-6d6e-43e1-8702-93fdf84e4dbc.h5ad | W9: https://cellxgene.cziscience.com/collections/854c0855-23ad-4362-8b77-6b1639e7a9fc | X9: 2
A10: 人 Human | B10: 肠神经/消化道 | C10: ascending colon | D10: Homo sapiens | E10: L4 | F10: L4:Intestinal enteroendocrine cell | H10: a48f5033-3438-4550-8574-cdff3263fdfd | I10: CELLxGENE:e40c6272-af77-4a10-9385-62a398884f27 | J10: HTAN VUMC - Differential pre-malignant programs and microenvironment chart distinct paths to malignancy in human colorectal polyps | K10: HTAN VUMC - 差异性的癌前程序与微环境描绘了人类结直肠息肉中通向恶性肿瘤的不同路径 | L10: 2022 | M10: 10.1016/j.cell.2021.11.031 | N10: ascending colon|descending colon|hepatic cecum|hepatic flexure of colon|rectum|sigmoid colon|transverse colon | O10: colon sessile serrated adenoma/polyp|colorectal neoplasm|hyperplastic polyp|normal|tubular adenoma|tubulovillous adenoma | P10: TruDrop | Q10: cell | R10: 65088 | S10: intestinal enteroendocrine cell | T10: CHGA;CHGB;NEUROD1;PAX6;GCG | U10: general peripheral neurobiology | V10: https://datasets.cellxgene.cziscience.com/9da034b0-de48-47ab-97f6-21b5f2dbd1a4.h5ad | W10: https://cellxgene.cziscience.com/collections/a48f5033-3438-4550-8574-cdff3263fdfd | X10: 2
A11: 人 Human | B11: 肠神经/消化道 | C11: blood | D11: Homo sapiens | E11: L4 | F11: L4:Enterochromaffin-like cell/Intestinal enteroendocrine cell | G11: 含泛glial(疑肠胶质,可能L2) | H11: 7f7fdf50-aa0e-4a6f-979c-53655cac9d5d | I11: CELLxGENE:0e5c75da-7bc9-4a2c-83fc-ef1e378bd5f9 | J11: IBDverse: Cell type-resolved genetic variation shapes inflammatory bowel disease risk | K11: IBDverse：细胞类型解析的遗传变异塑造炎症性肠病风险 | L11: 2026 | M11: 10.1038/s41586-026-10627-z | N11: blood|ileum|rectum | O11: Crohn disease|normal | P11: 10x 3' v3 | Q11: cell | R11: 1852681 | S11: enterochromaffin-like cell|glial cell|intestinal enteroendocrine cell | T11: SOX10;PLP1;S100B;GFRA3;FABP7 | U11: 神经-免疫通讯;炎症 | V11: https://datasets.cellxgene.cziscience.com/e3460364-c300-4616-9923-3a0224894998.h5ad | W11: https://cellxgene.cziscience.com/collections/7f7fdf50-aa0e-4a6f-979c-53655cac9d5d | X11: 1
A12: 人 Human | B12: 肠神经/消化道 | C12: body of stomach | D12: Homo sapiens | E12: L1;L4 | F12: L1:Peripheral nervous system neuron | L4:Enteroendocrine cell | G12: 含泛glial(疑肠胶质,可能L2) | H12: dfc09a93-bce0-4c77-893d-e153d1b7f9fa | I12: CELLxGENE:9968be68-ab65-4a38-9e1a-c9b6abece194 | J12: Charting human development using a multi-endodermal organ atlas and organoid models | K12: 利用多内胚层器官图谱与类器官模型描绘人类发育过程 | L12: 2023 | M12: 10.1016/j.cell.2021.04.028 | N12: body of stomach|colon|duodenum|epithelium of trachea|esophagus|ileum|jejunum|liver|lung|pyloric antrum|small intestine|stomach | O12: normal | P12: 10x 3' v2|10x 3' v3 | Q12: cell | R12: 155232 | S12: enteroendocrine cell|glial cell|peripheral nervous system neuron | T12: SOX10;PLP1;S100B;GFRA3;FABP7 | U12: general peripheral neurobiology | V12: https://datasets.cellxgene.cziscience.com/00b80c9b-8dbd-45c1-8347-51fbe8bd150e.h5ad | W12: https://cellxgene.cziscience.com/collections/dfc09a93-bce0-4c77-893d-e153d1b7f9fa | X12: 2
A13: 人 Human | B13: 肠神经/消化道 | C13: body of stomach | D13: Homo sapiens | E13: L4 | F13: L4:Enteroendocrine cell/Type G enteroendocrine cell | H13: a18474f4-ff1e-4864-af69-270b956cee5b | I13: CELLxGENE:7bb64315-9e5a-41b9-9235-59acf9642a3e | J13: Single-cell RNA sequencing unifies developmental programs of Esophageal and Gastric Intestinal Metaplasia | K13: 单细胞RNA测序统一食管与胃肠化生的发育程序 | L13: 2023 | M13: 10.1158/2159-8290.cd-22-0824 | N13: body of stomach|cardia of stomach|colon|duodenum|esophagogastric junction|ileum|lower esophagus|rectum|submucosal esophageal gland | O13: Barrett esophagus|gastric cancer|gastric intestinal metaplasia|gastritis|normal | P13: 10x 3' v2|10x 3' v3|10x 5' v1 | Q13: cell | R13: 293823 | S13: P/D1 enteroendocrine cell|enteroendocrine cell|type G enteroendocrine cell | T13: CHGA;CHGB;NEUROD1;PAX6;GCG | U13: 神经-免疫通讯 | V13: https://datasets.cellxgene.cziscience.com/3b5ba887-80df-43db-8486-3fc03027a15e.h5ad | W13: https://cellxgene.cziscience.com/collections/a18474f4-ff1e-4864-af69-270b956cee5b | X13: 3
A14: 人 Human | B14: 肠神经/消化道 | C14: caecum | D14: Homo sapiens | E14: L4 | F14: L4:Enteroendocrine cell of colon | H14: 1cbfb478-2c7f-4d15-b522-9f74e9fe52a8 | I14: CELLxGENE:829a3cd1-a466-49f1-b2e9-d3f6b7f392e2 | J14: Progressive plasticity during colorectal cancer metastasis | K14: 结直肠癌转移过程中的渐进式可塑性 | L14: 2025 | M14: 10.1038/s41586-024-08560-0 | N14: caecum|chest wall|descending colon|hepatic flexure of colon|liver|lung|peritoneum|rectum|sigmoid colon|transverse colon | O14: colorectal cancer|normal | P14: 10x 3' v3 | Q14: cell | R14: 47107 | S14: enteroendocrine cell of colon | T14: CHGA;CHGB;NEUROD1;PAX6;GCG | U14: 神经-免疫通讯 | V14: https://datasets.cellxgene.cziscience.com/81bd8922-b69a-45ea-9b2a-032c480c0e37.h5ad | W14: https://cellxgene.cziscience.com/collections/1cbfb478-2c7f-4d15-b522-9f74e9fe52a8 | X14: 3
A15: 人 Human | B15: 肠神经/消化道 | C15: caecum epithelium | D15: Homo sapiens | E15: L4 | F15: L4:Enteroendocrine cell | H15: 33d19f34-87f5-455b-8ca5-9023a2e5453d | I15: CELLxGENE:4dd00779-7f73-4f50-89bb-e2d3c6b71b18 | J15: Intra- and Inter-cellular Rewiring of the Human Colon during Ulcerative Colitis | K15: 溃疡性结肠炎期间人结肠的细胞内与细胞间重连 | L15: 2023 | M15: 10.1016/j.cell.2019.06.029 | N15: caecum epithelium|colonic epithelium|transverse colon epithelium | O15: normal | P15: 10x 3' v1|10x 3' v2 | Q15: cell | R15: 34772 | S15: enteroendocrine cell | T15: CHGA;CHGB;NEUROD1;PAX6;GCG | U15: 神经-免疫通讯;炎症;伤口修复 | V15: https://datasets.cellxgene.cziscience.com/774d77e7-210d-4237-8ca8-8d2bb841a2e4.h5ad | W15: https://cellxgene.cziscience.com/collections/33d19f34-87f5-455b-8ca5-9023a2e5453d | X15: 1
A16: 人 Human | B16: 肠神经/消化道 | C16: colon | D16: Homo sapiens | E16: L1;L4 | F16: L1:Enteric neuron | L4:Enteroendocrine cell | H16: 17481d16-ee44-49e5-bcf0-28c0780d8c4a | I16: CELLxGENE:b46237d1-19c6-4af2-9335-9854634bad16 | J16: Single-Cell Sequencing of Developing Human Gut Reveals Transcriptional Links to Childhood Crohn’s Disease | K16: 发育中人类肠道的单细胞测序揭示与儿童克罗恩病的转录关联 | L16: 2022 | M16: 10.1016/j.devcel.2020.11.010 | N16: colon|duodeno-jejunal junction|ileum | O16: normal | P16: 10x 3' v2 | Q16: cell | R16: 62849 | S16: enteric neuron|enteroendocrine cell | T16: CHGA;CHGB;NEUROD1;PAX6;GCG | U16: 神经-免疫通讯;炎症 | V16: https://datasets.cellxgene.cziscience.com/5cf26393-87e2-4946-8a97-2d42625856a3.h5ad | W16: https://cellxgene.cziscience.com/collections/17481d16-ee44-49e5-bcf0-28c0780d8c4a | X16: 2
A17: 人 Human | B17: 肠神经/消化道 | C17: colon | D17: Homo sapiens | E17: L1;L4 | F17: L1:Inhibitory motor neuron/Interneuron (ENS)/Motor neuron | L4:Neuroendocrine cell | G17: 含泛glial(疑肠胶质,可能L2) | H17: 60358420-6055-411d-ba4f-e8ac80682a2e | I17: CELLxGENE:bbd16004-09e8-4b6c-b465-73ff83a52837 | J17: Spatiotemporal analysis of human intestinal development at single-cell resolution | K17: 单细胞分辨率下人类肠道发育的时空分析 | L17: 2021 | M17: 10.1016/j.cell.2020.12.016 | N17: colon|hindgut|ileum | O17: normal | P17: 10x 3' v3 | Q17: cell | R17: 4144 | S17: glial cell|inhibitory motor neuron|interneuron|motor neuron|neuroendocrine cell | T17: SOX10;PLP1;S100B;GFRA3;FABP7 | U17: general peripheral neurobiology | V17: https://datasets.cellxgene.cziscience.com/a40d9047-5990-4aa1-aac8-2ff55649dab5.h5ad | W17: https://cellxgene.cziscience.com/collections/60358420-6055-411d-ba4f-e8ac80682a2e | X17: 2
A18: 人 Human | B18: 肠神经/消化道 | C18: colorectum | D18: Homo sapiens | E18: L2;L4 | F18: L2:Schwann cell | L4:Enteroendocrine cell | H18: 4d82bd8e-8827-410b-8fc7-685b7dd92585 | I18: CELLxGENE:16023185-de21-4c0d-a9c8-73abdd52d142 | J18: Spatially organized multicellular immune hubs in human colorectal cancer | K18: 人类结直肠癌中空间组织的多细胞免疫枢纽 | L18: 2025 | M18: 10.1016/j.cell.2021.08.003 | N18: colorectum | O18: colon adenocarcinoma|normal | P18: 10x 3' v2|10x 3' v3 | Q18: cell | R18: 370115 | S18: Schwann cell|enteroendocrine cell | T18: SOX10;MPZ;PLP1;MBP;PMP22 | U18: 神经-免疫通讯;外周神经再生 | V18: https://datasets.cellxgene.cziscience.com/3d1f3641-5755-47e2-b797-10317d33fe32.h5ad | W18: https://cellxgene.cziscience.com/collections/4d82bd8e-8827-410b-8fc7-685b7dd92585 | X18: 3
A19: 人 Human | B19: 肠神经/消化道 | C19: duodenum | D19: Homo sapiens | E19: L2;L4 | F19: L2:Enteroglial cell | L4:Enteroendocrine cell of small intestine | H19: e5f58829-1a66-40b5-a624-9046778e74f5 | I19: CELLxGENE:a357414d-2042-4eb5-95f0-c58604a18bdd | J19: Tabula Sapiens | K19: Tabula Sapiens | L19: 2021 | M19: 10.1126/science.abl4896 | N19: duodenum|ileum|jejunum|small intestine | O19: normal | P19: 10x 3' v3|Smart-seq2 | Q19: cell | R19: 42036 | S19: enteroendocrine cell of small intestine|enteroglial cell | T19: SOX10;PLP1;S100B;GFRA3;FABP7 | U19: general peripheral neurobiology | V19: https://datasets.cellxgene.cziscience.com/6db4dfe6-d421-4287-a9dc-22eaa59be966.h5ad | W19: https://cellxgene.cziscience.com/collections/e5f58829-1a66-40b5-a624-9046778e74f5 | X19: 5
A20: 人 Human | B20: 肠神经/消化道 | C20: epithelium of small intestine | D20: Homo sapiens | E20: L4 | F20: L4:Type EC enteroendocrine cell/Type L enteroendocrine cell | H20: 5c868b6f-62c5-4532-9d7f-a346ad4b50a7 | I20: CELLxGENE:fe4b89d5-461e-440c-a5a8-621b37b122c0 | J20: The landscape of immune dysregulation in Crohn’s disease revealed through single-cell transcriptomic profiling in the ileum and colon | K20: 单细胞转录组谱分析揭示克罗恩病回肠与结肠免疫失调的全景 | L20: 2023 | M20: 10.1016/j.immuni.2023.01.002 | N20: epithelium of small intestine|ileal epithelium|ileum|ileum lamina propria|lamina propria of small intestine|small intestine | O20: Crohn disease|normal | P20: 10x 3' v2|10x 3' v3 | Q20: cell | R20: 154136 | S20: type EC enteroendocrine cell|type L enteroendocrine cell | T20: CHGA;CHGB;NEUROD1;PAX6;GCG | U20: 神经-免疫通讯;炎症 | V20: https://datasets.cellxgene.cziscience.com/6a6b7339-106f-420b-95ae-c8d2d91f9945.h5ad | W20: https://cellxgene.cziscience.com/collections/5c868b6f-62c5-4532-9d7f-a346ad4b50a7 | X20: 4
A21: 人 Human | B21: 肠神经/消化道 | C21: ileum | D21: Homo sapiens | E21: L4 | F21: L4:Enteroendocrine cell of colon | H21: ff668d5d-5b3f-49ee-a007-ff0664bf35ec | I21: CELLxGENE:248cf7bf-508b-4c28-a2fd-cabe2ab956aa | J21: Single-cell transcriptome analysis reveals differential nutrient absorption functions in human intestine | K21: 单细胞转录组分析揭示人肠道中差异性的营养吸收功能 | L21: 2022 | M21: 10.1084/jem.20191130 | N21: ileum | O21: normal | P21: 10x 3' v2 | Q21: cell | R21: 5980 | S21: enteroendocrine cell of colon | T21: CHGA;CHGB;NEUROD1;PAX6;GCG | U21: general peripheral neurobiology | V21: https://datasets.cellxgene.cziscience.com/685f053a-2204-489a-b166-1d0190406be6.h5ad | W21: https://cellxgene.cziscience.com/collections/ff668d5d-5b3f-49ee-a007-ff0664bf35ec | X21: 3
